<?xml version="1.0"?>
<robot xmlns:xacro="http://www.ros.org/wiki/xacro">
  <link name="omniwheel_link">
    <visual>
      <geometry>
        <mesh filename="file://$(find ow_peque_description)/meshes/RuedaOmnidireccional.stl" scale="0.001 0.001 0.001"/>
      </geometry>
      <origin xyz="0 0 0" rpy="0 0 0"/>
    </visual>
  </link>

  <joint name="omniwheel_joint" type="continuous">
    <parent link="base_link"/>
    <child link="omniwheel_link"/>
    <origin xyz="0 0 0" rpy="0 0 0"/>
    <axis xyz="0 0 1"/>
  </joint>

</robot>
